Workbook

Sheet Read Me & Dashboard
A1: MOZ-RRM Historical Alert & Severity Review | April–August 2026
L2: Status | M2: Count
A3: Purpose: historical registry and calibration workbook for the simplified RRM severity methodology. Alert-stage severity preserves what was reasonably knowable at alert time; RNA-stage severity updates only fields supported by the assessment. The registry status is provisional: alerts older than 80 days are marked Pending closure until closure is formally confirmed. | L3: Ongoing alert | M3: =COUNTIF('Alert Registry'!K2:K100,L3) -> 8
L4: Pending closure | M4: =COUNTIF('Alert Registry'!K2:K100,L4) -> 10
H5: Dashboard date | J5: =TODAY() -> 46311 | L5: Open - RNA pending | M5: =COUNTIF('Alert Registry'!K2:K100,L5) -> 0
A6: Dashboard KPIs
A8: Total alerts | C8: RNA completed | E8: Tier 2 assessments | G8: Ongoing alerts | I8: Pending closure | L8: Severity | M8: Alert | N8: RNA
A9: =COUNTA('Alert Registry'!A2:A100) -> 18 | C9: =COUNTIF('Alert Registry'!F2:F100,"Yes") -> 16 | E9: =COUNTIF('Alert Registry'!G2:G100,"Yes") -> 1 | G9: =COUNTIF('Alert Registry'!K2:K100,"Ongoing alert") -> 8 | I9: =COUNTIF('Alert Registry'!K2:K100,"Pending closure") -> 10 | L9: Low | M9: =COUNTIF('Alert Registry'!L2:L100,L9) -> 0 | N9: =COUNTIF('Alert Registry'!M2:M100,L9) -> 0
L10: Moderate | M10: =COUNTIF('Alert Registry'!L2:L100,L10) -> 8 | N10: =COUNTIF('Alert Registry'!M2:M100,L10) -> 2
L11: High | M11: =COUNTIF('Alert Registry'!L2:L100,L11) -> 7 | N11: =COUNTIF('Alert Registry'!M2:M100,L11) -> 12
A12: No RNA | C12: Critical at alert | E12: Critical after RNA | G12: Severity changed | I12: Severity unchanged | L12: Critical | M12: =COUNTIF('Alert Registry'!L2:L100,L12) -> 3 | N12: =COUNTIF('Alert Registry'!M2:M100,L12) -> 3
A13: =COUNTIF('Alert Registry'!F2:F100,"No") -> 2 | C13: =COUNTIF('Alert Registry'!L2:L100,"Critical") -> 3 | E13: =COUNTIF('Alert Registry'!M2:M100,"Critical") -> 3 | G13: =COUNTA('Alert Registry'!N2:N19)-COUNTIF('Alert Registry'!N2:N19,"No change") -> 8 | I13: =COUNTIF('Alert Registry'!N2:N100,"No change") -> 10
A16: How to use this workbook
A17: 1 | B17: Alert Registry | C17: Master list of reviewed alerts, RNA/Tier 2 completion, days open, provisional status, and severity change.
A18: 2 | B18: Severity - Alert | C18: Historical alert-stage evidence and provisional severity using the simplified two-domain framework.
A19: 3 | B19: Severity - RNA | C19: Updated evidence following RNA. Where no RNA updated a point, alert-stage information is retained.
A20: 4 | B20: Severity Framework | C20: Short methodology, domain anchors, ≥900 override, confidence/completeness principles and status thresholds.
A21: 5 | B21: Important | C21: Namuno/Muanona is intentionally scored at both stages; the RNA Critical result carries a geographic-evidence caveat because onward arrival locations were not separately assessed.
A40: Dashboard interpretation notes
A41: • Alerts older than 80 days are marked Pending closure as a conservative interim status; formal closure confirmation is still required.
A42: • A completed RNA does not automatically close an alert. Alerts ≤80 days with RNA are shown as Ongoing alert.
A43: • Severity is categorical, not additive. Overall severity is the highest supported domain level unless the ≥900 HH Critical override applies.
A44: • Vulnerable groups, host pressure, access constraints and response coverage inform interpretation but are not independent point scores.
A45: • RNA-stage values retain alert-stage information wherever the RNA did not provide an update.

Sheet Alert Registry
A1: Alert Name | B1: Organisation | C1: Arrival District | D1: Alert Shared Date | E1: Movement Type | F1: RNA Done? | G1: Tier 2 Assessment Done? | H1: RNA Date | I1: Tier 2 Date | J1: Days from Alert to Today | K1: Status | L1: Alert Severity | M1: RNA Severity | N1: Change | O1: Population Type | P1: Alert Caseload | Q1: Latest / RNA Caseload | R1: Linked to Previous Alert? | S1: Related Alert(s) | T1: Alert Source File | U1: RNA Source File | V1: Tier 2 Source File | W1: Notes
A2: RRM_IOMDTM_MULTI-DISTRICT_18042026_IDP | B2: IOM/DTM | C2: Multiple districts | D2: 46130 | E2: Mixed reactive + pre-emptive/fear-driven | F2: Yes | G2: No | H2: 46162 | J2: =TODAY()-D2 -> 181 | K2: =IF(J2>'Severity Framework'!$B$4,"Pending closure",IF(F2="Yes","Ongoing alert","Open - RNA pending")) -> Pending closure | L2: Moderate | M2: High | N2: =IF(OR(L2="",M2=""),"",IF(VLOOKUP(M2,'Severity Framework'!$J$3:$K$6,2,FALSE)=VLOOKUP(L2,'Severity Framework'!$J$3:$K$6,2,FALSE),"No change",IF(VLOOKUP(M2,'Severity Framework'!$J$3:$K$6,2,FALSE)>VLOOKUP(L2,'Severity Framework'!$J$3:$K$6,2,FALSE),"↑"& (VLOOKUP(M2,'Severity Framework'!$J$3:$K$6,2,FALSE)-VLOOKUP(L2,'Severity Framework'!$J$3:$K$6,2,FALSE)) &" level","↓"& ABS(VLOOKUP(M2,'Severity Framework'!$J$3:$K$6,2,FALSE)-VLOOKUP(L2,'Severity Framework'!$J$3:$K$6,2,FALSE)) &" level"))) -> ↑1 level | O2: IDP | P2: 177 HH / 573 people | Q2: 177 HH / 573 people retained; no replacement alert-wide caseload | R2: No | T2: Mozambique — ETT Movement Alert Report #153 — Macomia & Muidumbe attacks (18 April 2026).pdf | U2: RRM_ACF_MACOMIA_IDP_RNA_20052026.pdf
A3: RRM_NRC_NANGADE_22042026_IDP | B3: NRC | C3: Nangade | D3: 46134 | E3: Mixed reactive + fear-driven | F3: Yes | G3: No | H3: 46160 | J3: =TODAY()-D3 -> 177 | K3: =IF(J3>'Severity Framework'!$B$4,"Pending closure",IF(F3="Yes","Ongoing alert","Open - RNA pending")) -> Pending closure | L3: Moderate | M3: High | N3: =IF(OR(L3="",M3=""),"",IF(VLOOKUP(M3,'Severity Framework'!$J$3:$K$6,2,FALSE)=VLOOKUP(L3,'Severity Framework'!$J$3:$K$6,2,FALSE),"No change",IF(VLOOKUP(M3,'Severity Framework'!$J$3:$K$6,2,FALSE)>VLOOKUP(L3,'Severity Framework'!$J$3:$K$6,2,FALSE),"↑"& (VLOOKUP(M3,'Severity Framework'!$J$3:$K$6,2,FALSE)-VLOOKUP(L3,'Severity Framework'!$J$3:$K$6,2,FALSE)) &" level","↓"& ABS(VLOOKUP(M3,'Severity Framework'!$J$3:$K$6,2,FALSE)-VLOOKUP(L3,'Severity Framework'!$J$3:$K$6,2,FALSE)) &" level"))) -> ↑1 level | O3: IDP | P3: ~190 HH | Q3: 227 affected HH across Nangade | R3: No | T3: RRM_NRC_NANG_22042026PDF.pdf | U3: RRM_NRC_NANGADE_IDP_RNA_18052026.pdf
A4: RRM_SCI_MTAMBA_28042026_IDP | B4: SCI | C4: TBC | D4: 46140 | E4: Reactive | F4: No | G4: No | J4: =TODAY()-D4 -> 171 | K4: =IF(J4>'Severity Framework'!$B$4,"Pending closure",IF(F4="Yes","Ongoing alert","Open - RNA pending")) -> Pending closure | L4: Moderate | M4: Moderate | N4: =IF(OR(L4="",M4=""),"",IF(VLOOKUP(M4,'Severity Framework'!$J$3:$K$6,2,FALSE)=VLOOKUP(L4,'Severity Framework'!$J$3:$K$6,2,FALSE),"No change",IF(VLOOKUP(M4,'Severity Framework'!$J$3:$K$6,2,FALSE)>VLOOKUP(L4,'Severity Framework'!$J$3:$K$6,2,FALSE),"↑"& (VLOOKUP(M4,'Severity Framework'!$J$3:$K$6,2,FALSE)-VLOOKUP(L4,'Severity Framework'!$J$3:$K$6,2,FALSE)) &" level","↓"& ABS(VLOOKUP(M4,'Severity Framework'!$J$3:$K$6,2,FALSE)-VLOOKUP(L4,'Severity Framework'!$J$3:$K$6,2,FALSE)) &" level"))) -> No change | O4: IDP | P4: 80 HH linked to Mitope; ~140 other recent arrivals already at centre | Q4: 80 HH linked to Mitope; ~140 other recent arrivals already at centre | R4: Potential | S4: RRM_NRC_NANGADE_22042026_IDP | T4: RRM_SCI_MdP_27042026_final.pdf | W4: Arrival district/AP remains TBC.
A5: RRM_SI_ANCUABE_04052026_IDP | B5: SI | C5: Ancuabe | D5: 46146 | E5: Reactive; movement ongoing | F5: Yes | G5: No | H5: 46162 | J5: =TODAY()-D5 -> 165 | K5: =IF(J5>'Severity Framework'!$B$4,"Pending closure",IF(F5="Yes","Ongoing alert","Open - RNA pending")) -> Pending closure | L5: Critical | M5: Critical | N5: =IF(OR(L5="",M5=""),"",IF(VLOOKUP(M5,'Severity Framework'!$J$3:$K$6,2,FALSE)=VLOOKUP(L5,'Severity Framework'!$J$3:$K$6,2,FALSE),"No change",IF(VLOOKUP(M5,'Severity Framework'!$J$3:$K$6,2,FALSE)>VLOOKUP(L5,'Severity Framework'!$J$3:$K$6,2,FALSE),"↑"& (VLOOKUP(M5,'Severity Framework'!$J$3:$K$6,2,FALSE)-VLOOKUP(L5,'Severity Framework'!$J$3:$K$6,2,FALSE)) &" level","↓"& ABS(VLOOKUP(M5,'Severity Framework'!$J$3:$K$6,2,FALSE)-VLOOKUP(L5,'Severity Framework'!$J$3:$K$6,2,FALSE)) &" level"))) -> No change | O5: IDP | P5: 1,573 HH / ~3,950 people | Q5: 1,573 HH / 3,950 people retained | R5: No | T5: SI_ANC_04052026.pdf | U5: RRM_SI_ANCUABE_IDP_RNA_20052026.pdf
A6: RRM_NRC_MONTEPUEZ_06052026_IDP | B6: NRC | C6: Montepuez | D6: 46148 | E6: Mixed, predominantly reactive | F6: Yes | G6: Yes | H6: 46161 | I6: 46191 | J6: =TODAY()-D6 -> 163 | K6: =IF(J6>'Severity Framework'!$B$4,"Pending closure",IF(F6="Yes","Ongoing alert","Open - RNA pending")) -> Pending closure | L6: High | M6: High | N6: =IF(OR(L6="",M6=""),"",IF(VLOOKUP(M6,'Severity Framework'!$J$3:$K$6,2,FALSE)=VLOOKUP(L6,'Severity Framework'!$J$3:$K$6,2,FALSE),"No change",IF(VLOOKUP(M6,'Severity Framework'!$J$3:$K$6,2,FALSE)>VLOOKUP(L6,'Severity Framework'!$J$3:$K$6,2,FALSE),"↑"& (VLOOKUP(M6,'Severity Framework'!$J$3:$K$6,2,FALSE)-VLOOKUP(L6,'Severity Framework'!$J$3:$K$6,2,FALSE)) &" level","↓"& ABS(VLOOKUP(M6,'Severity Framework'!$J$3:$K$6,2,FALSE)-VLOOKUP(L6,'Severity Framework'!$J$3:$K$6,2,FALSE)) &" level"))) -> No change | O6: IDP | P6: ~500 HH | Q6: 626 affected HH; final caseload still requires verification | R6: Potential | S6: RRM_SI_ANCUABE_04052026_IDP | T6: RRM_NRC_NACU_06052026_PDF.pdf | U6: RRM_NRC_MONTEPUEZ_IDP_RNA_19052026.pdf | V6: RRM_NRC_MONTEPUEZ_IDP_TIER2-RNA_18062026.docx
A7: RRM_SI_CHIURE_19052026_IDP | B7: SI | C7: Chiúre | D7: 46161 | E7: Mixed reactive + fear-driven | F7: Yes | G7: No | H7: 46174 | J7: =TODAY()-D7 -> 150 | K7: =IF(J7>'Severity Framework'!$B$4,"Pending closure",IF(F7="Yes","Ongoing alert","Open - RNA pending")) -> Pending closure | L7: High | M7: High | N7: =IF(OR(L7="",M7=""),"",IF(VLOOKUP(M7,'Severity Framework'!$J$3:$K$6,2,FALSE)=VLOOKUP(L7,'Severity Framework'!$J$3:$K$6,2,FALSE),"No change",IF(VLOOKUP(M7,'Severity Framework'!$J$3:$K$6,2,FALSE)>VLOOKUP(L7,'Severity Framework'!$J$3:$K$6,2,FALSE),"↑"& (VLOOKUP(M7,'Severity Framework'!$J$3:$K$6,2,FALSE)-VLOOKUP(L7,'Severity Framework'!$J$3:$K$6,2,FALSE)) &" level","↓"& ABS(VLOOKUP(M7,'Severity Framework'!$J$3:$K$6,2,FALSE)-VLOOKUP(L7,'Severity Framework'!$J$3:$K$6,2,FALSE)) &" level"))) -> No change | O7: IDP | P7: 889 HH + unknown hosted HH | Q7: 889 HH + unknown hosted HH retained; exact caseload still requires verification | R7: Potential | S7: RRM_SI_ANCUABE_04052026_IDP | T7: SI_CHR_19052026.pdf | U7: RRM_SI_CHIURE_IDP_RNA_01062026.pdf
A8: RRM_SCI_MOCIMBOA-DA-PRAIA_26052026_IDP | B8: SCI | C8: Mocímboa da Praia | D8: 46168 | E8: Reactive | F8: No | G8: No | J8: =TODAY()-D8 -> 143 | K8: =IF(J8>'Severity Framework'!$B$4,"Pending closure",IF(F8="Yes","Ongoing alert","Open - RNA pending")) -> Pending closure | L8: Moderate | M8: Moderate | N8: =IF(OR(L8="",M8=""),"",IF(VLOOKUP(M8,'Severity Framework'!$J$3:$K$6,2,FALSE)=VLOOKUP(L8,'Severity Framework'!$J$3:$K$6,2,FALSE),"No change",IF(VLOOKUP(M8,'Severity Framework'!$J$3:$K$6,2,FALSE)>VLOOKUP(L8,'Severity Framework'!$J$3:$K$6,2,FALSE),"↑"& (VLOOKUP(M8,'Severity Framework'!$J$3:$K$6,2,FALSE)-VLOOKUP(L8,'Severity Framework'!$J$3:$K$6,2,FALSE)) &" level","↓"& ABS(VLOOKUP(M8,'Severity Framework'!$J$3:$K$6,2,FALSE)-VLOOKUP(L8,'Severity Framework'!$J$3:$K$6,2,FALSE)) &" level"))) -> No change | O8: IDP | P8: ~300 HH | Q8: ~300 HH | R8: Potential | S8: RRM_SCI_MTAMBA_28042026_IDP | T8: RRM_SCI_MDP_26052026.pdf
A9: RRM_SCI_NAMUNO-MONTEPUEZ_26052026_IDP | B9: SCI | C9: Namuno & Montepuez | D9: 46168 | E9: Reactive | F9: Yes | G9: No | H9: 46190 | J9: =TODAY()-D9 -> 143 | K9: =IF(J9>'Severity Framework'!$B$4,"Pending closure",IF(F9="Yes","Ongoing alert","Open - RNA pending")) -> Pending closure | L9: High | M9: Critical | N9: =IF(OR(L9="",M9=""),"",IF(VLOOKUP(M9,'Severity Framework'!$J$3:$K$6,2,FALSE)=VLOOKUP(L9,'Severity Framework'!$J$3:$K$6,2,FALSE),"No change",IF(VLOOKUP(M9,'Severity Framework'!$J$3:$K$6,2,FALSE)>VLOOKUP(L9,'Severity Framework'!$J$3:$K$6,2,FALSE),"↑"& (VLOOKUP(M9,'Severity Framework'!$J$3:$K$6,2,FALSE)-VLOOKUP(L9,'Severity Framework'!$J$3:$K$6,2,FALSE)) &" level","↓"& ABS(VLOOKUP(M9,'Severity Framework'!$J$3:$K$6,2,FALSE)-VLOOKUP(L9,'Severity Framework'!$J$3:$K$6,2,FALSE)) &" level"))) -> ↑1 level | O9: IDP | P9: ~500 HH affected at Muanona; displaced-arrival caseload not quantified | Q9: ~500 affected HH retained; displaced-arrival caseload still not verified | R9: No | T9: RRM_SCI_NAMNO_26052026.pdf | U9: RRM_SCI_NAMUNO_MONTEPUEZ_IDP_RNA_17062026.pdf | W9: RNA-stage Critical is scored with a geographic-evidence caveat: Muanona was assessed, while reported onward-arrival locations were not separately assessed.
A10: RRM_SI_ANCUABE_08062026_IDP | B10: SI | C10: Ancuabe | D10: 46181 | E10: Reactive; movement ongoing | F10: Yes | G10: No | H10: 46192 | J10: =TODAY()-D10 -> 130 | K10: =IF(J10>'Severity Framework'!$B$4,"Pending closure",IF(F10="Yes","Ongoing alert","Open - RNA pending")) -> Pending closure | L10: Moderate | M10: High | N10: =IF(OR(L10="",M10=""),"",IF(VLOOKUP(M10,'Severity Framework'!$J$3:$K$6,2,FALSE)=VLOOKUP(L10,'Severity Framework'!$J$3:$K$6,2,FALSE),"No change",IF(VLOOKUP(M10,'Severity Framework'!$J$3:$K$6,2,FALSE)>VLOOKUP(L10,'Severity Framework'!$J$3:$K$6,2,FALSE),"↑"& (VLOOKUP(M10,'Severity Framework'!$J$3:$K$6,2,FALSE)-VLOOKUP(L10,'Severity Framework'!$J$3:$K$6,2,FALSE)) &" level","↓"& ABS(VLOOKUP(M10,'Severity Framework'!$J$3:$K$6,2,FALSE)-VLOOKUP(L10,'Severity Framework'!$J$3:$K$6,2,FALSE)) &" level"))) -> ↑1 level | O10: IDP | P10: ~735 HH | Q10: ~735 HH retained; verification still needed | R10: Yes | S10: RRM_SI_ANCUABE_04052026_IDP; RRM_SI_ANCUABE_31072026_RETURNEE | T10: SI_ANC_08062026.pdf | U10: RRM_SI_ANCUABE_IDP_RNA_19062026.docx
A11: RRM_NRC_MONTEPUEZ_17062026_IDP | B11: NRC | C11: Montepuez | D11: 46190 | E11: Mixed, predominantly reactive | F11: Yes | G11: No | H11: 46204 | J11: =TODAY()-D11 -> 121 | K11: =IF(J11>'Severity Framework'!$B$4,"Pending closure",IF(F11="Yes","Ongoing alert","Open - RNA pending")) -> Pending closure | L11: High | M11: High | N11: =IF(OR(L11="",M11=""),"",IF(VLOOKUP(M11,'Severity Framework'!$J$3:$K$6,2,FALSE)=VLOOKUP(L11,'Severity Framework'!$J$3:$K$6,2,FALSE),"No change",IF(VLOOKUP(M11,'Severity Framework'!$J$3:$K$6,2,FALSE)>VLOOKUP(L11,'Severity Framework'!$J$3:$K$6,2,FALSE),"↑"& (VLOOKUP(M11,'Severity Framework'!$J$3:$K$6,2,FALSE)-VLOOKUP(L11,'Severity Framework'!$J$3:$K$6,2,FALSE)) &" level","↓"& ABS(VLOOKUP(M11,'Severity Framework'!$J$3:$K$6,2,FALSE)-VLOOKUP(L11,'Severity Framework'!$J$3:$K$6,2,FALSE)) &" level"))) -> No change | O11: IDP | P11: ~650 HH | Q11: ~650 HH retained; exact caseload requires verification | R11: Yes | S11: RRM_NRC_MONTEPUEZ_06052026_IDP | T11: RRM_NRC_NSA_17062026.pdf | U11: RRM_NRC_MONTEPUEZ_IDP_RNA_01072026.pdf
A12: RRM_NRC_MONTEPUEZ_29072026_IDP | B12: NRC | C12: Montepuez | D12: 46232 | E12: Predominantly pre-emptive / fear-driven | F12: Yes | G12: No | H12: 46247 | J12: =TODAY()-D12 -> 79 | K12: =IF(J12>'Severity Framework'!$B$4,"Pending closure",IF(F12="Yes","Ongoing alert","Open - RNA pending")) -> Ongoing alert | L12: High | M12: High | N12: =IF(OR(L12="",M12=""),"",IF(VLOOKUP(M12,'Severity Framework'!$J$3:$K$6,2,FALSE)=VLOOKUP(L12,'Severity Framework'!$J$3:$K$6,2,FALSE),"No change",IF(VLOOKUP(M12,'Severity Framework'!$J$3:$K$6,2,FALSE)>VLOOKUP(L12,'Severity Framework'!$J$3:$K$6,2,FALSE),"↑"& (VLOOKUP(M12,'Severity Framework'!$J$3:$K$6,2,FALSE)-VLOOKUP(L12,'Severity Framework'!$J$3:$K$6,2,FALSE)) &" level","↓"& ABS(VLOOKUP(M12,'Severity Framework'!$J$3:$K$6,2,FALSE)-VLOOKUP(L12,'Severity Framework'!$J$3:$K$6,2,FALSE)) &" level"))) -> No change | O12: IDP | P12: >884 HH | Q12: 884 HH currently reported; new arrivals still ongoing | R12: No | T12: MOZ-RRM_26.07.2026_Montepuez_Mirate_NRC.pdf | U12: RRM_NRC_MONTEPUEZ_IDP_RNA_13082026.docx
A13: RRM_SI_ANCUABE_31072026_IDP | B13: SI | C13: Ancuabe | D13: 46234 | E13: Reactive | F13: Yes | G13: No | H13: 46247 | J13: =TODAY()-D13 -> 77 | K13: =IF(J13>'Severity Framework'!$B$4,"Pending closure",IF(F13="Yes","Ongoing alert","Open - RNA pending")) -> Ongoing alert | L13: Moderate | M13: High | N13: =IF(OR(L13="",M13=""),"",IF(VLOOKUP(M13,'Severity Framework'!$J$3:$K$6,2,FALSE)=VLOOKUP(L13,'Severity Framework'!$J$3:$K$6,2,FALSE),"No change",IF(VLOOKUP(M13,'Severity Framework'!$J$3:$K$6,2,FALSE)>VLOOKUP(L13,'Severity Framework'!$J$3:$K$6,2,FALSE),"↑"& (VLOOKUP(M13,'Severity Framework'!$J$3:$K$6,2,FALSE)-VLOOKUP(L13,'Severity Framework'!$J$3:$K$6,2,FALSE)) &" level","↓"& ABS(VLOOKUP(M13,'Severity Framework'!$J$3:$K$6,2,FALSE)-VLOOKUP(L13,'Severity Framework'!$J$3:$K$6,2,FALSE)) &" level"))) -> ↑1 level | O13: IDP | P13: ~265 HH | Q13: ~260 displaced HH | R13: Potential | S13: RRM_SI_ANCUABE_04052026_IDP | T13: Alert_SI_ANC_31072026_ IDP's.docx | U13: RRM_SI_ANCUABE_IDP_RNA_13082026.pdf
A14: RRM_SI_ANCUABE_31072026_RETURNEE | B14: SI | C14: Ancuabe | D14: 46234 | E14: Return | F14: Yes | G14: No | H14: 46253 | J14: =TODAY()-D14 -> 77 | K14: =IF(J14>'Severity Framework'!$B$4,"Pending closure",IF(F14="Yes","Ongoing alert","Open - RNA pending")) -> Ongoing alert | L14: Critical | M14: Critical | N14: =IF(OR(L14="",M14=""),"",IF(VLOOKUP(M14,'Severity Framework'!$J$3:$K$6,2,FALSE)=VLOOKUP(L14,'Severity Framework'!$J$3:$K$6,2,FALSE),"No change",IF(VLOOKUP(M14,'Severity Framework'!$J$3:$K$6,2,FALSE)>VLOOKUP(L14,'Severity Framework'!$J$3:$K$6,2,FALSE),"↑"& (VLOOKUP(M14,'Severity Framework'!$J$3:$K$6,2,FALSE)-VLOOKUP(L14,'Severity Framework'!$J$3:$K$6,2,FALSE)) &" level","↓"& ABS(VLOOKUP(M14,'Severity Framework'!$J$3:$K$6,2,FALSE)-VLOOKUP(L14,'Severity Framework'!$J$3:$K$6,2,FALSE)) &" level"))) -> No change | O14: Returnee | P14: ~3,495 HH | Q14: ~3,495 HH retained from alert; RNA labels current returnee caseload TBC/unverified | R14: Yes | S14: RRM_SI_ANCUABE_04052026_IDP; RRM_SI_ANCUABE_08062026_IDP | T14: Alert_SI_ANC_31072026_ Returnee.docx | U14: RRM_SI_ANCUABE_RETURNEE_RNA_19082026.pdf
A15: RRM_ACF_QUISSANGA_11082026_IDP | B15: ACF | C15: Quissanga | D15: 46245 | E15: Reactive / fear-driven | F15: Yes | G15: No | H15: 46251 | J15: =TODAY()-D15 -> 66 | K15: =IF(J15>'Severity Framework'!$B$4,"Pending closure",IF(F15="Yes","Ongoing alert","Open - RNA pending")) -> Ongoing alert | L15: High | M15: High | N15: =IF(OR(L15="",M15=""),"",IF(VLOOKUP(M15,'Severity Framework'!$J$3:$K$6,2,FALSE)=VLOOKUP(L15,'Severity Framework'!$J$3:$K$6,2,FALSE),"No change",IF(VLOOKUP(M15,'Severity Framework'!$J$3:$K$6,2,FALSE)>VLOOKUP(L15,'Severity Framework'!$J$3:$K$6,2,FALSE),"↑"& (VLOOKUP(M15,'Severity Framework'!$J$3:$K$6,2,FALSE)-VLOOKUP(L15,'Severity Framework'!$J$3:$K$6,2,FALSE)) &" level","↓"& ABS(VLOOKUP(M15,'Severity Framework'!$J$3:$K$6,2,FALSE)-VLOOKUP(L15,'Severity Framework'!$J$3:$K$6,2,FALSE)) &" level"))) -> No change | O15: IDP | P15: 457 HH / 819 people | Q15: 457 HH / 819 people retained; caseload still requires verification | R15: No | T15: Alert_ACF_QUI_11082026_ IDPs..pdf | U15: RRM_ACF_QUISSANGA_IDP_RNA_17082026.pdf | W15: RNA geography wording (Natugo 1 AP) should be reconciled with alert geography (Napuda/Mahate).
A16: RRM_SCI_BALAMA_19082026_IDP | B16: SCI | C16: Balama | D16: 46253 | E16: Reactive; movement ongoing | F16: Yes | G16: No | H16: 46266 | J16: =TODAY()-D16 -> 58 | K16: =IF(J16>'Severity Framework'!$B$4,"Pending closure",IF(F16="Yes","Ongoing alert","Open - RNA pending")) -> Ongoing alert | L16: High | M16: High | N16: =IF(OR(L16="",M16=""),"",IF(VLOOKUP(M16,'Severity Framework'!$J$3:$K$6,2,FALSE)=VLOOKUP(L16,'Severity Framework'!$J$3:$K$6,2,FALSE),"No change",IF(VLOOKUP(M16,'Severity Framework'!$J$3:$K$6,2,FALSE)>VLOOKUP(L16,'Severity Framework'!$J$3:$K$6,2,FALSE),"↑"& (VLOOKUP(M16,'Severity Framework'!$J$3:$K$6,2,FALSE)-VLOOKUP(L16,'Severity Framework'!$J$3:$K$6,2,FALSE)) &" level","↓"& ABS(VLOOKUP(M16,'Severity Framework'!$J$3:$K$6,2,FALSE)-VLOOKUP(L16,'Severity Framework'!$J$3:$K$6,2,FALSE)) &" level"))) -> No change | O16: IDP | P16: ~100 HH confirmed in Mavala Sede; additional HH in Nseue B/Npaca unknown | Q16: 250 displaced HH: 136 Mavala Sede + 114 Nseue B; Npaca not updated | R16: No | T16: RRM_SCI_BALAMA_08082026.pdf | U16: RRM_SCI_BALAMA_IDP_RNA_01092026.pdf
A17: RRM_ACF_MACOMIA_10092026_IDP | B17: ACF | C17: Macomia | D17: 46275 | E17: Reactive; arrivals ongoing | F17: Yes | G17: No | H17: 46282 | J17: =TODAY()-D17 -> 36 | K17: =IF(J17>'Severity Framework'!$B$4,"Pending closure",IF(F17="Yes","Ongoing alert","Open - RNA pending")) -> Ongoing alert | L17: Moderate | M17: High | N17: =IF(OR(L17="",M17=""),"",IF(VLOOKUP(M17,'Severity Framework'!$J$3:$K$6,2,FALSE)=VLOOKUP(L17,'Severity Framework'!$J$3:$K$6,2,FALSE),"No change",IF(VLOOKUP(M17,'Severity Framework'!$J$3:$K$6,2,FALSE)>VLOOKUP(L17,'Severity Framework'!$J$3:$K$6,2,FALSE),"↑"& (VLOOKUP(M17,'Severity Framework'!$J$3:$K$6,2,FALSE)-VLOOKUP(L17,'Severity Framework'!$J$3:$K$6,2,FALSE)) &" level","↓"& ABS(VLOOKUP(M17,'Severity Framework'!$J$3:$K$6,2,FALSE)-VLOOKUP(L17,'Severity Framework'!$J$3:$K$6,2,FALSE)) &" level"))) -> ↑1 level | O17: IDP | P17: 98 HH arrived as of 7 Sep; screening/registration ongoing and further arrivals expected | Q17: 98 HH retained from alert; 15 Sep KII estimated ~140 people at the site, not directly comparable; registration data needed | R17: Potential | S17: RRM_IOMDTM_MULTI-DISTRICT_18042026_IDP | T17: RRM_ACF_MACOMIA_10092026_ IDPs.pdf | U17: RRM_ACF_MACOMIA_IDP_RNA_17092026.pdf | W17: New September shock and distinct caseload, but Nonge-Muagamula already hosts former/protracted IDPs. RNA sample included 7 alert-linked and 5 protracted IDP households.
A18: RRM_NRC_NANGADE_15092026_IDP | B18: NRC | C18: Nangade | D18: 46280 | E18: Mixed reactive + pre-emptive/fear-driven | F18: Yes | G18: No | H18: 46286 | J18: =TODAY()-D18 -> 31 | K18: =IF(J18>'Severity Framework'!$B$4,"Pending closure",IF(F18="Yes","Ongoing alert","Open - RNA pending")) -> Ongoing alert | L18: Moderate | M18: High | N18: ↑1 level | O18: IDP | P18: 176 HH newly arrived in Ntamba IDP site and host community | Q18: 176 HH retained from alert; RNA KIs estimated ~475 displaced people on average, a different unit that should not replace the HH figure | R18: Potential | S18: RRM_NRC_NANGADE_22042026_IDP; RRM_SCI_MTAMBA_28042026_IDP | T18: RRM_NRC_NANGADE_15092026_IDP.docx | U18: RRM_NRC_NANGADE_IDP_RNA_21092026.docx | W18: New September displacement to Ntamba. Potential contextual linkage to earlier alerts because Nkonga/Muangaza also appeared in the April Nangade alert and Mitope appeared in the April SCI alert; this should not be treated as the same caseload without household-level confirmation.
A19: RRR_NRC_NANG_30092026 | B19: NRC | C19: Nangade | D19: 46296 | E19: Mixed reactive + fear-driven, moveent ongoing | F19: yes | G19: No | K19: =IF(J19>'Severity Framework'!$B$4,"Pending closure",IF(F19="Yes","Ongoing alert","Open - RNA pending")) -> Ongoing alert | L19: Critical | N19: =IF(OR(L19="",M19=""),"",IF(VLOOKUP(M19,'Severity Framework'!$J$3:$K$6,2,FALSE)=VLOOKUP(L19,'Severity Framework'!$J$3:$K$6,2,FALSE),"No change",IF(VLOOKUP(M19,'Severity Framework'!$J$3:$K$6,2,FALSE)>VLOOKUP(L19,'Severity Framework'!$J$3:$K$6,2,FALSE),"↑"& (VLOOKUP(M19,'Severity Framework'!$J$3:$K$6,2,FALSE)-VLOOKUP(L19,'Severity Framework'!$J$3:$K$6,2,FALSE)) &" level","↓"& ABS(VLOOKUP(M19,'Severity Framework'!$J$3:$K$6,2,FALSE)-VLOOKUP(L19,'Severity Framework'!$J$3:$K$6,2,FALSE)) &" level"))) | O19: IDP | P19: 1040 HH newly arrived in Ntamaba and Muadi | R19: No | T19: RRM_NRC_NANG_3009226

Sheet Severity - Alert
A1: Alert Name | B1: Organisation | C1: Stage Date | D1: Arrival District | E1: Arrival AP / Locations | F1: Origin District | G1: Origin AP / Locations | H1: Shock Type | I1: Movement Type | J1: Population Type | K1: Potential Link to Previous Alert? | L1: Related Alert(s) | M1: Relationship | N1: Caseload Estimate | O1: Vulnerable Populations Reported | P1: Needs / Acute Conditions Flagged | Q1: Host Already Hosting IDPs? | R1: Existing Tensions? | S1: Other Protection Threats at Arrival / Current Area | T1: Accessibility | U1: Humanitarian Conditions Domain | V1: Protection / Ongoing Threat Domain | W1: ≥900 HH Override? | X1: Completeness / Geographic Coverage | Y1: Confidence | Z1: Severity | AA1: Short Rationale | AB1: Source File
A2: RRM_IOMDTM_MULTI-DISTRICT_18042026_IDP | B2: IOM/DTM | C2: 46130 | D2: Multiple districts | E2: Macomia locality; Chitunda AP; Muidumbe AP; Imbuo AP; Ibo AP: Macomia; Chitunda; Muidumbe; Namacande; Imbuhu; Vila do Ibo | F2: Macomia & Muidumbe | G2: Not consistently stated: Nkoe; Nguida; Macomia; Chai; Pangane; Miengueleva | H2: NSAG attacks / insecurity | I2: Mixed reactive + pre-emptive/fear-driven | J2: IDP | K2: No | N2: 177 HH / 573 people | O2: Children 52%; 18 pregnant women; 14 older people; 9 persons with disabilities; 1 unaccompanied child | P2: Food, shelter and NFIs flagged; current severity at destinations insufficiently described | Q2: Some arrivals to existing sites/host communities | R2: Not reported | S2: General insecurity; no specific imminent threat at destinations described | T2: Not sufficiently described in the ETT alert | U2: Level 2 - Moderate | V2: Level 2 - Moderate | W2: No | X2: Partial | Y2: Low | Z2: Moderate | AA2: Clear needs and vulnerable groups, but limited evidence on actual severity of current conditions at the destinations. | AB2: Mozambique — ETT Movement Alert Report #153 — Macomia & Muidumbe attacks (18 April 2026).pdf
A3: RRM_NRC_NANGADE_22042026_IDP | B3: NRC | C3: 46134 | D3: Nangade | E3: Not stated: Mualela IDP site | F3: Nangade | G3: Not stated: Nkonga; Samora Machel; Namajonda; Muangaz; Litingina; Machava | H3: Armed attacks / NSAG movement | I3: Mixed reactive + fear-driven | J3: IDP | K3: No | N3: ~190 HH | O3: Older people, women and children | P3: Shelter, food, WASH and NFIs | Q3: Yes - Mualela is an IDP site | R3: Not reported | S3: No specific threat at arrival reported | T3: Good/feasible; route described as relatively calm | U3: Level 2 - Moderate | V3: Level 1 - Low | W3: No | X3: Partial | Y3: Medium | Z3: Moderate | AA3: Needs were largely generic and no severe current deprivation at Mualela was yet demonstrated. | AB3: RRM_NRC_NANG_22042026PDF.pdf
A4: RRM_SCI_MTAMBA_28042026_IDP | B4: SCI | C4: 46140 | D4: TBC | E4: TBC: Mtamba | F4: Mocímboa da Praia | G4: Diaca: Mitope | H4: Armed attack | I4: Reactive | J4: IDP | K4: Potential | L4: RRM_NRC_NANGADE_22042026_IDP | M4: Possible contextual overlap because Muangaza/Samora Machel also appear among prior recent arrivals; same households not confirmed | N4: 80 HH linked to Mitope; ~140 other recent arrivals already at centre | O4: Older people, women and children | P4: Shelter, food, WASH and NFIs | Q4: Yes - other recent displaced households were already present | R4: Not reported | S4: Route relatively calm; no recent incident reported | T4: Good/feasible for light and heavy vehicles | U4: Level 2 - Moderate | V4: Level 1 - Low | W4: No | X4: Partial | Y4: Medium | Z4: Moderate | AA4: Additional hosting pressure is plausible, but actual current living conditions were insufficiently described. | AB4: RRM_SCI_MdP_27042026_final.pdf
A5: RRM_SI_ANCUABE_04052026_IDP | B5: SI | C5: 46146 | D5: Ancuabe | E5: Not stated: Nanjua A; Nanjua B; Muaja; Majasse; Nsanja | F5: Ancuabe | G5: Not stated: Minheuene; Nacole; Muaja | H5: Multiple armed attacks, destruction and abductions | I5: Reactive; movement ongoing | J5: IDP | K5: No | N5: 1,573 HH / ~3,950 people | O5: Pregnant women, older people, people with chronic illness, children | P5: Food, NFIs, shelter / rapid response recommended | Q5: Not clearly stated | R5: Not reported | S5: Movement continuing; security forces patrolling | T5: Limited information | U5: Insufficient information | V5: Level 2 - Moderate | W5: Yes - ≥900 HH | X5: Partial | Y5: High | Z5: Critical | AA5: Automatic consortium Critical threshold because the alert-linked caseload is ≥900 HH. | AB5: SI_ANC_04052026.pdf
A6: RRM_NRC_MONTEPUEZ_06052026_IDP | B6: NRC | C6: 46148 | D6: Montepuez | E6: Not stated in alert: Namanhumbire | F6: Ancuabe | G6: Not stated: Nacuja; Nacaca; Campire | H6: Armed attack + fear of further attacks | I6: Mixed, predominantly reactive | J6: IDP | K6: Potential | L6: RRM_SI_ANCUABE_04052026_IDP | M6: Contextually linked to the wider Ancuabe escalation but follows a new 5 May shock and remains a separate caseload | N6: ~500 HH | O6: Older people, women and children | P6: Food, WASH and basic NFIs; families initially gathered at community meeting point | Q6: Residents providing immediate support | R6: Not reported | S6: NSAG activity reported near the N14 / operational route; security clearance required | T6: Feasible but constrained by distance, potholes, checkpoints and security monitoring | U6: Level 2 - Moderate | V6: Level 3 - High | W6: No | X6: Partial | Y6: Medium | Z6: High | AA6: Continuing security threat affecting movement/access supports High despite limited arrival-condition detail. | AB6: RRM_NRC_NACU_06052026_PDF.pdf
A7: RRM_SI_CHIURE_19052026_IDP | B7: SI | C7: 46161 | D7: Chiúre | E7: Not stated: Megarruma; Maningane A; Maningane B; Chiúre host neighbourhoods | F7: Ancuabe & Chiúre | G7: Metoro (Namacuili); others not stated: Namacuili; Navigi; wider incident narrative includes Namania and neighbouring villages | H7: Armed attacks / population movement | I7: Mixed reactive + fear-driven | J7: IDP | K7: Potential | L7: RRM_SI_ANCUABE_04052026_IDP | M7: Wider Ancuabe–Chiúre escalation; same-household overlap not established | N7: 889 HH + unknown hosted HH | O7: Not specifically quantified in the alert | P7: Food, NFIs and shelter | Q7: Yes - IDP sites and host households | R7: Not reported | S7: Attacks reportedly ongoing in neighbouring areas; households moved more than once before reaching current hosting locations | T7: Feasible but degraded N1, potholes and checkpoints | U7: Level 2 - Moderate | V7: Level 3 - High | W7: Possible - total may exceed 900 HH | X7: Partial | Y7: Medium | Z7: High | AA7: Nearby continuing insecurity supports High. Known caseload is 889 HH plus an unquantified hosted population, requiring urgent threshold verification. | AB7: SI_CHR_19052026.pdf
A8: RRM_SCI_MOCIMBOA-DA-PRAIA_26052026_IDP | B8: SCI | C8: 46168 | D8: Mocímboa da Praia | E8: Not stated: Milamba; Ntende; Nanduadua; Airport peri-urban area; Tende | F8: Mocímboa da Praia | G8: Not stated: Nabaje; Moma; Naquiero | H8: Recurrent NSAG attacks | I8: Reactive | J8: IDP | K8: Potential | L8: RRM_SCI_MTAMBA_28042026_IDP | M8: Contextual continuation of insecurity in Mocímboa da Praia, but a separate origin and caseload | N8: ~300 HH | O8: Injured people; women and children prioritised | P8: Emergency shelter, food, WASH, psychosocial support and protection | Q8: Hosted by relatives / host communities | R8: Not reported | S8: Exact conditions and security of dispersed arrival population not known | T8: Road access and UNHAS possible | U8: Level 2 - Moderate | V8: Level 2 - Moderate | W8: No | X8: Partial | Y8: Low | Z8: Moderate | AA8: Serious shock but insufficient evidence of severe current conditions at the dispersed arrival locations. | AB8: RRM_SCI_MDP_26052026.pdf
A9: RRM_SCI_NAMUNO-MONTEPUEZ_26052026_IDP | B9: SCI | C9: 46168 | D9: Namuno & Montepuez | E9: Meloco town / other destinations unresolved: Reported movement toward Meloco town, Montepuez District and other safer communities | F9: Namuno | G9: Meloco: Muanona | H9: Armed NSAG attack; killings, burning, looting and destruction | I9: Reactive | J9: IDP | K9: No | N9: ~500 HH affected at Muanona; displaced-arrival caseload not quantified | O9: Vulnerable groups referenced generally; protection particularly noted for children and women | P9: Families reportedly fled with few belongings; shelter, food, hygiene/WASH, protection, basic services and household items; psychosocial support | Q9: Arrival hosting situation unknown | R9: Unknown | S9: Wider environment highly volatile; continued NSAG presence/activity and significant protection concerns | T9: Origin/surrounding access highly constrained; onward Montepuez route poor and 6–7 hours | U9: Level 3 - High | V9: Level 3 - High | W9: No | X9: Partial / arrival geography unresolved | Y9: Low | Z9: High | AA9: Scored despite incomplete arrival data: reactive displacement, multiple immediate needs and a highly volatile environment support a provisional High, but not Critical. | AB9: RRM_SCI_NAMNO_26052026.pdf
A10: RRM_SI_ANCUABE_08062026_IDP | B10: SI | C10: 46181 | D10: Ancuabe | E10: Ancuabe Sede + Nanjua (AP not stated): Nanjua; Ancuabe Sede; Nanhomane; Ntuto | F10: Ancuabe | G10: Not stated: Nanune; Nnaua; Nonia | H10: Repeated armed attacks, killings, abductions and burned houses | I10: Reactive; movement ongoing | J10: IDP | K10: Yes | L10: RRM_SI_ANCUABE_04052026_IDP; RRM_SI_ANCUABE_31072026_RETURNEE | M10: New June displacement wave in the same wider Ancuabe crisis; later return alert explicitly links returns to these earlier waves | N10: ~735 HH | O10: 53 pregnant women; 28 persons with disabilities; 35 older people | P10: Food, NFIs and shelter | Q10: Some receiving locations were already hosting IDPs | R10: Not reported | S10: Receiving area described as relatively stable despite continued displacement from attacks | T10: Feasible with poor-road sections; 4x4/truck possible | U10: Level 2 - Moderate | V10: Level 2 - Moderate | W10: No | X10: Partial | Y10: Medium | Z10: Moderate | AA10: Large caseload and vulnerabilities warrant attention, but severe current conditions at arrival were not yet documented. | AB10: SI_ANC_08062026.pdf
A11: RRM_NRC_MONTEPUEZ_17062026_IDP | B11: NRC | C11: 46190 | D11: Montepuez | E11: Not stated in alert: Namanhumbire; Ucuburi; Chimoio; Nanhupo-A | F11: Chiúre / other neighbouring areas | G11: Not consistently stated: Nsanja; Nacaca; Campire; Ncole/Nacole; Minheuene | H11: Armed attack / insecurity / fear | I11: Mixed, predominantly reactive | J11: IDP | K11: Yes | L11: RRM_NRC_MONTEPUEZ_06052026_IDP | M11: Potential overlap/cumulative hosting in Namanhumbire; some repeated origins, so caseload overlap required checking | N11: ~650 HH | O11: Women, children and elderly reported as majority | P11: Food, WASH and basic NFIs | Q11: Yes - Namanhumbire had already received the May caseload | R11: Not reported | S11: NSAG activity reported near N14; security clearance required | T11: Feasible but constrained by potholes, checkpoints and security clearance | U11: Level 2 - Moderate | V11: Level 3 - High | W11: No | X11: Partial | Y11: Medium | Z11: High | AA11: Continuing security environment affecting movement/access supports High; overlap with the earlier Namanhumbire caseload required screening. | AB11: RRM_NRC_NSA_17062026.pdf
A12: RRM_NRC_MONTEPUEZ_29072026_IDP | B12: NRC | C12: 46232 | D12: Montepuez | E12: Mirate: Mararange; Mavala; Mavanda | F12: Montepuez | G12: Mirate area: Nicocue; Namoro; Nquewene; Ntole | H12: NSAG movement / abduction incident / fear of attack | I12: Predominantly pre-emptive / fear-driven | J12: IDP | K12: No | N12: >884 HH | O12: None specifically reported | P12: Food, water/WASH, NFIs, shelter, health and protection | Q12: Hosted by host communities | R12: Not reported | S12: NSAGs remained active relatively close to N14; security clearance required | T12: Feasible but security constrained; paved but poor road, checkpoints and monitoring | U12: Level 2 - Moderate | V12: Level 3 - High | W12: Possible - count >884 HH and arrivals ongoing | X12: Partial | Y12: Medium | Z12: High | AA12: Protection/access environment supports High. The known count is extremely close to the ≥900 Critical threshold. | AB12: MOZ-RRM_26.07.2026_Montepuez_Mirate_NRC.pdf
A13: RRM_NRC_MONTEPUEZ_29072026_IDP | B13: SI | C13: 46234 | D13: Ancuabe | E13: Mesa: Muaja | F13: Meluco | G13: Not stated: Mitepo | H13: Armed attack, abductions, houses burned and looted | I13: Reactive | J13: IDP | K13: Potential | L13: RRM_SI_ANCUABE_04052026_IDP | M13: Muaja had previously hosted IDPs from earlier Ancuabe displacement, but this is a new July shock and population | N13: ~265 HH | O13: None specifically reported | P13: Food, NFIs and shelter | Q13: Muaja had previously hosted IDPs; current burden unclear | R13: Not reported | S13: Arrival area described as relatively stable | T13: Good/feasible | U13: Level 2 - Moderate | V13: Level 1 - Low | W13: No | X13: Partial | Y13: Medium | Z13: Moderate | AA13: Current severe deprivation or an immediate protection threat at Muaja was not demonstrated in the alert. | AB13: Alert_SI_ANC_31072026_ IDP's.docx
A14: RRM_NRC_MONTEPUEZ_29072026_IDP | B14: SI | C14: 46234 | D14: Ancuabe | E14: Mesa: Nacueja/Nacoja; Minheuene; Nanune; Naua/Nonia | F14: Previous displacement locations in Ancuabe | G14: Mixed / not consistently stated: Nanjua A/site; Muaja; Majasse; Nsanja; Ancuabe Sede; Nanhomane; Ntuto | H14: Return following conflict displacement | I14: Return | J14: Returnee | K14: Yes | L14: RRM_SI_ANCUABE_04052026_IDP; RRM_SI_ANCUABE_08062026_IDP | M14: Explicit return of populations displaced by the late-April/early-May and June Ancuabe attack waves | N14: ~3,495 HH | O14: None newly specified in alert | P14: Food, NFIs and shelter broadly flagged | Q14: N/A - households returning to areas of origin | R14: Not reported | S14: Former attack areas; current security described as relatively stable | T14: Good/feasible | U14: Insufficient information | V14: Level 2 - Moderate | W14: Yes - ≥900 HH | X14: Partial | Y14: High | Z14: Critical | AA14: Automatic Critical under the consortium ≥900 HH threshold. | AB14: Alert_SI_ANC_31072026_ Returnee.docx
A15: RRM_ACF_QUISSANGA_11082026_IDP | B15: ACF | C15: 46245 | D15: Quissanga | E15: Mahate: Napuda | F15: Quissanga | G15: Mahate: Natugo | H15: Armed attack / abductions / fear | I15: Reactive / fear-driven | J15: IDP | K15: No | N15: 457 HH / 819 people | O15: 349 children; 22 older people; 8 persons with disabilities | P15: Most in makeshift shelter; no safe water; open excavations near river; nearest health facility ~15 km; food support had been received | Q15: Population described as relatively isolated from host communities | R15: Not reported | S15: NSAG presence remained a concern; four children remained missing from the incident | T15: Feasible by 4x4/truck; unpaved section vulnerable to erosion/rain | U15: Level 3 - High | V15: Level 2 - Moderate | W15: No | X15: Good for alert stage | Y15: High | Z15: High | AA15: High is driven by verified current arrival conditions, especially unsafe water, inadequate shelter and limited health access. | AB15: Alert_ACF_QUI_11082026_ IDPs..pdf
A16: RRM_SCI_BALAMA_19082026_IDP | B16: SCI | C16: 46253 | D16: Balama | E16: Balama: Nseue B; Mavala Sede; Npaca | F16: Balama | G16: Balama: Messalo River area | H16: Armed attacks / burned houses | I16: Reactive; movement ongoing | J16: IDP | K16: No | N16: ~100 HH confirmed in Mavala Sede; additional HH in Nseue B/Npaca unknown | O16: Women and children highlighted for protection | P16: Shelter, NFIs, food, WASH, protection and psychosocial support | Q16: Receiving host communities | R16: Not reported | S16: Recent attacks in the area; movement ongoing; security assessment required before intervention | T16: Mavala ~19 km from Balama; other distances unclear; security assessment required | U16: Level 2 - Moderate | V16: Level 3 - High | W16: No | X16: Partial | Y16: Medium | Z16: High | AA16: Recent security events, continued movement and need for security assessment support High despite limited arrival-condition detail. | AB16: RRM_SCI_BALAMA_08082026.pdf
A17: RRM_ACF_MACOMIA_10092026_IDP | B17: ACF | C17: 46275 | D17: Macomia | E17: Macomia Sede: Nonge-Muagamula Centre | F17: Macomia | G17: AP not stated: Litandacua; Novo Cabo | H17: NSAG attacks / looting / burning / destruction | I17: Reactive; arrivals ongoing | J17: IDP | K17: Potential | L17: RRM_IOMDTM_MULTI-DISTRICT_18042026_IDP | M17: New September shock and distinct caseload, but the same established receiving site already hosts former/protracted IDPs, creating potential cumulative pressure and contextual linkage to earlier Macomia displacement. | N17: 98 HH arrived as of 7 Sep; screening/registration ongoing and additional arrivals expected | O17: No specific vulnerable groups quantified in the alert | P17: Most families fled without household assets or personal belongings and have limited resources; hosted by relatives, friends and former IDPs; no humanitarian assistance reported; food, shelter, NFIs, protection, WASH and health require verification | Q17: Yes - former IDPs already settled in the centre are hosting new arrivals and sharing food | R17: Not reported | S17: Ongoing security concerns prevent return; no specific imminent protection threat at Nonge-Muagamula was reported | T17: Relatively easy humanitarian access via N1/N380; centre approximately 5 km from Macomia town | U17: Level 2 - Moderate | V17: Level 2 - Moderate | W17: No | X17: Partial - arrival conditions require RNA verification | Y17: High | Z17: Moderate | AA17: The alert confirms displacement, no formal assistance, asset loss and pressure on an existing IDP site, but does not yet verify severe acute gaps or an immediate threat at the arrival site. Moderate is therefore appropriate with high source confidence. | AB17: RRM_ACF_MACOMIA_10092026_ IDPs.pdf
A18: RRM_NRC_NANGADE_15092026_IDP | B18: NRC | C18: 46280 | D18: Nangade | E18: Ntamba Administrative Post: Ntamba IDP site and host community / village of Ntamba | F18: Nangade & Mocímboa da Praia | G18: Nangade origins: Ngalonga, Liché, Nkonga, Nambedo, Muangaza; Mocímboa da Praia origins: Mitope, Chinda, 30 de Junho neighbourhood and Mocímboa da Praia | H18: Armed attacks / NSAG movements / fear of attacks and abductions | I18: Mixed reactive + pre-emptive/fear-driven | J18: IDP | K18: Potential | L18: RRM_NRC_NANGADE_22042026_IDP; RRM_SCI_MTAMBA_28042026_IDP | M18: Recurrent insecurity affected some locations also seen in earlier alerts, but this is a new September shock and a distinct flow to Ntamba; same households are not confirmed. | N18: 176 HH newly arrived in Ntamba IDP site and host community | O18: Older people, women and children reported as vulnerable; no disaggregated counts | P18: Urgent needs flagged across food, shelter, NFIs, protection, WASH and health, but the alert does not document the actual severity of those gaps at arrival | Q18: Yes / likely - arrivals are staying in an IDP site and host community; the alert does not quantify the pre-existing IDP caseload | R18: Not reported | S18: Fear of attacks and abductions drove movement; no specific current threat at Ntamba was reported and the Mueda–Ntamba route was described as relatively calm | T18: Good/feasible: about 40 km / 1 hour from Mueda; generally good road, light and heavy vehicles can pass; routine checkpoints | U18: Level 2 - Moderate | V18: Level 2 - Moderate | W18: No | X18: Partial - severity of current arrival conditions not yet verified | Y18: High | Z18: Moderate | AA18: The alert confirms 176 newly arrived households, vulnerable groups and multi-sector needs, but it does not yet demonstrate severe acute conditions at Ntamba. The arrival route was relatively calm and accessible, so the provisional severity is Moderate. | AB18: RRM_NRC_NANGADE_15092026_IDP.docx
A19: RRM_NRC_NANGADE_30092026 | B19: NRC | C19: 46296 | D19: Nangade | E19: Ntamba IDP site and host community and Muadi IDP site | F19: Mocimboa da Praia and Nangade | G19: In Mocimboa da Praia district in the villages of Mitope, Chinda, Mocimboa da Praia sede, Maputo, Quelimane, Diaca, Chinda, Mitope, Pangela and from Nangade sistrict people are coming from the villages of Ngalonga, Nambedo, Samora Machel, Namuavica, Nambuembe, Lijungo, and Litingina | H19: Armed attack + fear of further attacks | I19: Mixed reactive + fear-driven, movement ongoing | J19: IDP | K19: No | M19: Contextual continuation of insecurity in both Nangade and Mocimboa da Praia distric due to NSAG sporadic attacks | N19: 1040 HH newly arrived in Ntamba and Muadi | O19: elders, women, and children were reported as vulnerables with urgent need of lifesaving humaniatrian assistance | P19: Food, shelter, non-food itms, protection, water, sanitation and hygiene (WASH), and health needs | Q19: Yes - in Ntamba in particlurly there were repor indication that some of newly arrived are staying in host community | R19: Not reported | S19: Protection was reported as need at broader level with not specific details on the services required | T19: Access feable from Mueda to Ntamba and Muadi, covering approximately 50 km, in about one hour. Rout relatively calm with no recent security incidents reported. Road condition are generally good, allowing both light and heavy vehicles to move without major constrains. | U19: Level 3 - High | V19: Level 2 - Moderate | W19: Yes - ≥900 HH | X19: Partial | Y19: High | Z19: Critical | AA19: Automatic Critical under the consortium ≥900 HH threshold. | AB19: RRM_NRC_NANG_3009226

Sheet Severity - RNA
A1: Alert Name | B1: Organisation | C1: Stage Date | D1: Arrival District | E1: Arrival AP / Locations | F1: Origin District | G1: Origin AP / Locations | H1: Shock Type | I1: Movement Type | J1: Population Type | K1: Potential Link to Previous Alert? | L1: Related Alert(s) | M1: Relationship | N1: Caseload Estimate | O1: Vulnerable Populations Reported | P1: Needs / Acute Conditions Flagged | Q1: Host Already Hosting IDPs? | R1: Existing Tensions? | S1: Other Protection Threats at Arrival / Current Area | T1: Accessibility | U1: Humanitarian Conditions Domain | V1: Protection / Ongoing Threat Domain | W1: ≥900 HH Override? | X1: Completeness / Geographic Coverage | Y1: Confidence | Z1: Severity | AA1: Short Rationale | AB1: Source File | AC1: Change vs Alert
A2: RRM_IOMDTM_MULTI-DISTRICT_18042026_IDP | B2: IOM/DTM | C2: 46162 | D2: Macomia (assessed); other alert destinations retained | E2: Muagamula/Muagamula-Nonje; AP not stated: Muagamula assessed; other alert destinations not reassessed | F2: Macomia & Muidumbe | G2: Not consistently stated: Alert origins retained | H2: NSAG attacks / insecurity | I2: Mixed; new arrivals continuing | J2: IDP | K2: No | N2: 177 HH / 573 people retained; no replacement alert-wide caseload | O2: Children, pregnant women, older people, PwD; child/nutrition concerns | P2: Serious shelter/NFI needs; serious food access constraints; unprotected wells/surface water; insufficient safe water; sanitation concerns; some shelters flooded and abandoned | Q2: Host/borrowed housing common | R2: No host tensions reported by KIs | S2: No current major protection concern reported at assessed site; site darkness flagged as a potential concern | T2: Good: ~15 min from Macomia Sede; no major physical obstacles or unsafe route sections observed; checkpoint present | U2: Level 3 - High | V2: Level 1 - Low | W2: No | X2: Partial geographic RNA coverage | Y2: Medium | Z2: High | AA2: RNA demonstrates several simultaneous serious current needs at the assessed arrival location; other destinations were not reassessed. | AB2: RRM_ACF_MACOMIA_IDP_RNA_20052026.pdf | AC2: =VLOOKUP(A2,'Alert Registry'!$A$2:$N$19,14,FALSE) -> ↑1 level
A3: RRM_NRC_NANGADE_22042026_IDP | B3: NRC | C3: 46160 | D3: Nangade | E3: Not stated: Mualela and Ntamba assessed; arrivals also reported in Muadi/Ntole | F3: Nangade | G3: Not stated: Alert origins retained | H3: Conflict / NSAG insecurity | I3: Ongoing reactive/fear-driven displacement | J3: IDP | K3: No | N3: 227 affected HH across Nangade | O3: Older people, women, children; child health/nutrition and pregnant/BF nutrition concerns | P3: Severe food constraints; poor/uninhabitable shelters; some homelessness; non-functional water systems; surface/purchased water; overcrowded/damaged latrines and open defecation | Q3: Hosting confirmed | R3: Some tensions around land, services and assistance | S3: Some residual conflict/security concerns; insecurity mainly prevents return | T3: Generally feasible; alert access description retained where RNA did not supersede it | U3: Level 3 - High | V3: Level 2 - Moderate | W3: No | X3: RNA conducted in key receiving locations | Y3: Medium | Z3: High | AA3: RNA converts generic needs into evidence of multiple serious current gaps in food, shelter and WASH. | AB3: RRM_NRC_NANGADE_IDP_RNA_18052026.pdf | AC3: =VLOOKUP(A3,'Alert Registry'!$A$2:$N$19,14,FALSE) -> ↑1 level
A4: RRM_SCI_MTAMBA_28042026_IDP | B4: SCI | D4: TBC | E4: TBC: Mtamba | F4: Mocímboa da Praia | G4: Diaca: Mitope | H4: Armed attack | I4: Reactive | J4: IDP | K4: Potential | L4: RRM_NRC_NANGADE_22042026_IDP | M4: Possible contextual overlap because Muangaza/Samora Machel also appear among prior recent arrivals; same households not confirmed | N4: 80 HH linked to Mitope; ~140 other recent arrivals already at centre | O4: Older people, women and children | P4: Shelter, food, WASH and NFIs | Q4: Yes - other recent displaced households were already present | R4: Not reported | S4: Route relatively calm; no recent incident reported | T4: Good/feasible for light and heavy vehicles | U4: Level 2 - Moderate | V4: Level 1 - Low | W4: No | X4: No RNA - alert values retained | Y4: Medium | Z4: Moderate | AA4: No RNA was provided, so the alert-stage severity and supporting information are retained. | AB4: RRM_SCI_MdP_27042026_final.pdf | AC4: =VLOOKUP(A4,'Alert Registry'!$A$2:$N$19,14,FALSE) -> No change
A5: RRM_SI_ANCUABE_04052026_IDP | B5: SI | C5: 46162 | D5: Ancuabe | E5: Nanjua A/B assessed; AP not stated: Nanjua A and Nanjua B assessed; Muaja/Majasse/Nsanja retained but not reassessed | F5: Ancuabe | G5: Not stated: Minheuene; Nacole; Muaja | H5: Multiple armed attacks, destruction and abductions | I5: Reactive; arrivals ongoing | J5: IDP | K5: No | N5: 1,573 HH / 3,950 people retained | O5: Children; pregnant women; older people; chronic illness; women/girls and PwD facing heightened risks/barriers | P5: 88% food-access problems; 83% reduced meals; emergency shelter/NFI gaps; health access barriers; WASH constraints; psychosocial distress and missing documentation | Q5: Strong reliance on host-family accommodation | R5: Host pressure and potential tensions over land, services and assistance | S5: Armed violence, theft/looting, harassment/extortion and documentation problems reported; psychosocial distress widespread | T5: No clear replacement route classification; alert limitations retained | U5: Level 3 - High | V5: Level 3 - High | W5: Yes - ≥900 HH | X5: Partial geographic coverage; override unambiguous | Y5: High | Z5: Critical | AA5: Critical remains driven by the ≥900 HH consortium rule; RNA independently confirms substantial current needs. | AB5: RRM_SI_ANCUABE_IDP_RNA_20052026.pdf | AC5: =VLOOKUP(A5,'Alert Registry'!$A$2:$N$19,14,FALSE) -> No change
A6: RRM_NRC_MONTEPUEZ_06052026_IDP | B6: NRC | C6: 46161 | D6: Montepuez | E6: Namanhumbir: Namanhumbire; later Tier 2 primarily Nanhupo and Ecubure/Ucuburi | F6: Ancuabe | G6: Not stated: Nacuja and nearby origins | H6: Armed attack / fear | I6: Ongoing displacement | J6: IDP; Tier 2 sample later mixed | K6: Potential | L6: RRM_SI_ANCUABE_04052026_IDP | M6: Wider Ancuabe–Montepuez crisis; distinct 5 May displacement flow | N6: 626 affected HH; final caseload still requires verification | O6: Children, women/girls, older people, PwD, children under 5, pregnant/BF women; Tier 2 also identifies female-headed HH | P6: Severe food access; negative coping; severe/immediate shelter/NFI gaps; overcrowded sanitation; many HH with very limited safe water; nutrition concerns; Tier 2 still found major food/shelter/WASH gaps after assistance | Q6: Host HH absorbing displacement; pressure on food, water and shelter | R6: No social tensions reported in initial RNA | S6: Few direct site concerns, but nearby insecurity and unsafe routes remained relevant | T6: Feasible with constraints: poor road/potholes, checkpoints and nearby insecure areas; Tier 2 follow-up broadly feasible | U6: Level 3 - High | V6: Level 2 - Moderate | W6: No | X6: Good for main receiving area; caseload verification still needed | Y6: High | Z6: High | AA6: High is firmly grounded in current food, shelter and WASH conditions; Tier 2 shows important residual needs remained. | AB6: RRM_NRC_MONTEPUEZ_IDP_RNA_19052026.pdf | AC6: =VLOOKUP(A6,'Alert Registry'!$A$2:$N$19,14,FALSE) -> No change
A7: RRM_SI_CHIURE_19052026_IDP | B7: SI | C7: 46174 | D7: Chiúre | E7: Maningane/Manicane and Megarruma assessed: Maningane/Manicane and Megarruma; host neighbourhoods retained | F7: Ancuabe & Chiúre | G7: Metoro / others not stated: Alert origins retained | H7: Conflict / armed attacks | I7: Reactive + fear-driven | J7: IDP | K7: Potential | L7: RRM_SI_ANCUABE_04052026_IDP | M7: Wider regional escalation; same-household overlap not established | N7: 889 HH + unknown hosted HH retained; exact caseload still requires verification | O7: PwD/reduced-mobility groups; some unaccompanied children observed | P7: 92% insufficient food; average 1.64 meals/day; 60% people without shelter; overcrowded/makeshift/open-air sleeping; 76% insufficient safe water; open defecation; health access often >60 min | Q7: Significant hosting pressure | R7: Relations generally good/sufficient despite pressure | S7: Unsafe routes/movement restrictions; missing documentation; poor lighting/privacy; UAC concerns | T7: Operational access possible but movement/protection concerns remain; alert road constraints retained | U7: Level 3 - High | V7: Level 3 - High | W7: Possible - total may exceed 900 HH | X7: Indicative; caseload threshold unresolved | Y7: High | Z7: High | AA7: RNA strongly confirms High through severe food, shelter, WASH and health-access gaps plus movement-related protection concerns. | AB7: RRM_SI_CHIURE_IDP_RNA_01062026.pdf | AC7: =VLOOKUP(A7,'Alert Registry'!$A$2:$N$19,14,FALSE) -> No change
A8: RRM_SCI_MOCIMBOA-DA-PRAIA_26052026_IDP | B8: SCI | D8: Mocímboa da Praia | E8: Not stated: Milamba; Ntende; Nanduadua; Airport peri-urban area; Tende | F8: Mocímboa da Praia | G8: Not stated: Nabaje; Moma; Naquiero | H8: Recurrent NSAG attacks | I8: Reactive | J8: IDP | K8: Potential | L8: RRM_SCI_MTAMBA_28042026_IDP | M8: Contextual continuation of insecurity in Mocímboa da Praia, but a separate origin and caseload | N8: ~300 HH | O8: Injured people; women and children prioritised | P8: Emergency shelter, food, WASH, psychosocial support and protection | Q8: Hosted by relatives / host communities | R8: Not reported | S8: Exact conditions and security of dispersed arrival population not known | T8: Road access and UNHAS possible | U8: Level 2 - Moderate | V8: Level 2 - Moderate | W8: No | X8: No RNA - alert values retained | Y8: Low | Z8: Moderate | AA8: No RNA was provided, so the alert-stage severity and supporting information are retained. | AB8: RRM_SCI_MDP_26052026.pdf | AC8: =VLOOKUP(A8,'Alert Registry'!$A$2:$N$19,14,FALSE) -> No change
A9: RRM_SCI_NAMUNO-MONTEPUEZ_26052026_IDP | B9: SCI | C9: 46190 | D9: Namuno / reported onward Montepuez not separately assessed | E9: Muanona, Meloco AP assessed; reported onward destinations unresolved: Assessment conducted in Muanona; reported onward arrivals toward Meloco town/Montepueze were not separately assessed | F9: Namuno | G9: Meloco: Muanona (also the assessed current area) | H9: Armed NSAG attack, destruction, deaths and looting | I9: Reactive; movement remained fluid | J9: Mixed alert-linked affected population | K9: No | N9: ~500 affected HH retained; displaced-arrival caseload still not verified | O9: Women/girls, children, older people, PwD, pregnant/BF women and other vulnerable groups | P9: 83% insufficient food; ~1.8 meals/day; 100% interviewed HH reported damaged/destroyed homes; severe visible shelter destruction; 83% insufficient safe water; sanitation problems; major medicine/staff gaps; nearest health centre reportedly empty | Q9: Mixed hosting/affected population; overcrowding/hosting pressure reported | R9: Community tensions/discrimination reported | S9: All KIIs and interviewed HH reported safety/protection concerns; unsafe routes/movement restrictions universal; threats/harassment, family separation, exploitation/abuse and HLP issues also reported | T9: Major constraint: poor/damaged sandy route, flooding/erosion/culvert damage; trucks could not access; immediate response judged not feasible | U9: Level 4 - Critical | V9: Level 4 - Critical | W9: No | X9: Scored with geographic-evidence caveat | Y9: Medium | Z9: Critical | AA9: Multiple concurrent extreme conditions meet the Critical threshold despite the assessment geography not matching all reported onward-arrival locations. | AB9: RRM_SCI_NAMUNO_MONTEPUEZ_IDP_RNA_17062026.pdf | AC9: =VLOOKUP(A9,'Alert Registry'!$A$2:$N$19,14,FALSE) -> ↑1 level
A10: RRM_SI_ANCUABE_08062026_IDP | B10: SI | C10: 46192 | D10: Ancuabe | E10: Mesa & Ancuabe APs: Nanjua and Ntuto assessed; other receiving locations retained | F10: Ancuabe | G10: Not stated: Nanune; Nnaua; Nonia | H10: Repeated armed attacks | I10: Reactive; movement fluid | J10: IDP | K10: Yes | L10: RRM_SI_ANCUABE_04052026_IDP; RRM_SI_ANCUABE_31072026_RETURNEE | M10: New June displacement wave in the wider Ancuabe crisis; later linked to return movement | N10: ~735 HH retained; verification still needed | O10: Pregnant/BF women, children, older people, PwD, newly arrived HH; family separation/UAC and GBV/SEA concerns | P10: 84% insufficient food; 1.45 meals/day; 79% people without shelter; major NFI gaps; 61% insufficient safe water; non-/partially functioning water points; sanitation gaps; healthcare and nutrition barriers | Q10: Many staying with hosts or in borrowed houses; visible hosting pressure | R10: Some tensions linked to unequal assistance, competition for resources, hosting pressure and rising prices | S10: 84% reported insecurity/unsafe movement; family separation/UAC, some GBV/SEA risk and one explosive-ordnance/civilian-casualty concern | T10: Feasible with constraints: roads fair/passable; light vehicles/trucks fully or partly accessible; insecurity and rainy-season deterioration | U10: Level 3 - High | V10: Level 3 - High | W10: No | X10: Indicative but adequate for alert-level review | Y10: High | Z10: High | AA10: RNA establishes simultaneous severe food, shelter and WASH deprivation plus protection concerns, increasing severity from Moderate to High. | AB10: RRM_SI_ANCUABE_IDP_RNA_19062026.docx | AC10: =VLOOKUP(A10,'Alert Registry'!$A$2:$N$19,14,FALSE) -> ↑1 level
